Traceback (most recent call last):
  File "/opt/hostedtoolcache/Python/3.7.11/x64/lib/python3.7/site-packages/jupyter_cache/executors/utils.py", line 56, in single_nb_execution
    record_timing=False,
  File "/opt/hostedtoolcache/Python/3.7.11/x64/lib/python3.7/site-packages/nbclient/client.py", line 1117, in execute
    return NotebookClient(nb=nb, resources=resources, km=km, **kwargs).execute()
  File "/opt/hostedtoolcache/Python/3.7.11/x64/lib/python3.7/site-packages/nbclient/util.py", line 78, in wrapped
    return just_run(coro(*args, **kwargs))
  File "/opt/hostedtoolcache/Python/3.7.11/x64/lib/python3.7/site-packages/nbclient/util.py", line 57, in just_run
    return loop.run_until_complete(coro)
  File "/opt/hostedtoolcache/Python/3.7.11/x64/lib/python3.7/asyncio/base_events.py", line 587, in run_until_complete
    return future.result()
  File "/opt/hostedtoolcache/Python/3.7.11/x64/lib/python3.7/site-packages/nbclient/client.py", line 559, in async_execute
    cell, index, execution_count=self.code_cells_executed + 1
  File "/opt/hostedtoolcache/Python/3.7.11/x64/lib/python3.7/site-packages/nbclient/client.py", line 862, in async_execute_cell
    self._check_raise_for_error(cell, exec_reply)
  File "/opt/hostedtoolcache/Python/3.7.11/x64/lib/python3.7/site-packages/nbclient/client.py", line 765, in _check_raise_for_error
    raise CellExecutionError.from_cell_and_msg(cell, exec_reply_content)
nbclient.exceptions.CellExecutionError: An error occurred while executing the following cell:
------------------
import ontolopy as opy
import pandas as pd 
from myst_nb import glue
import time

# Read in files:
# -------------
fantom_obo_file = '../c08-combining/data/experiments/fantom/ff-phase2-170801.obo.txt'
fantom_samples_info_file = '../c08-combining/data/experiments/fantom/fantom_humanSamples2.0.csv'
uberon_obo_file = '../c08-combining/data/uberon_ext_210321.obo' 

# Uberon OBO:
uberon_obo = opy.load_obo(
    file_loc=uberon_obo_file, 
    ont_ids=['GO', 'UBERON','CL'], 
)

# FANTOM OBO:
fantom_obo = opy.load_obo(
    file_loc=fantom_obo_file, 
    ont_ids=['CL', 'FF', 'GO', 'UBERON', 'DOID'],
)

# FANTOM Samples Info file:
fantom_samples_info = pd.read_csv(fantom_samples_info_file, index_col=1)


# Glue Samples Info excerpt:
# --------------------------
indices = [1,9,11]  # choose rows for variety
display(fantom_samples_info.iloc[indices])
glue("fantom-samples-info-excerpt", fantom_samples_info.iloc[indices], display=False)
------------------

[0;31m---------------------------------------------------------------------------[0m
[0;31mAttributeError[0m                            Traceback (most recent call last)
[0;32m/tmp/ipykernel_16443/1301224309.py[0m in [0;36m<module>[0;34m[0m
[1;32m     11[0m [0;34m[0m[0m
[1;32m     12[0m [0;31m# Uberon OBO:[0m[0;34m[0m[0;34m[0m[0;34m[0m[0m
[0;32m---> 13[0;31m uberon_obo = opy.load_obo(
[0m[1;32m     14[0m     [0mfile_loc[0m[0;34m=[0m[0muberon_obo_file[0m[0;34m,[0m[0;34m[0m[0;34m[0m[0m
[1;32m     15[0m     [0mont_ids[0m[0;34m=[0m[0;34m[[0m[0;34m'GO'[0m[0;34m,[0m [0;34m'UBERON'[0m[0;34m,[0m[0;34m'CL'[0m[0;34m][0m[0;34m,[0m[0;34m[0m[0;34m[0m[0m

[0;31mAttributeError[0m: module 'ontolopy' has no attribute 'load_obo'
AttributeError: module 'ontolopy' has no attribute 'load_obo'

